2024-07-11 18:28:06,593 ERROR: Exception on / [GET] [in C:\Users\15097\Desktop\FinalBlog\venv\Lib\site-packages\flask\app.py:838]
Traceback (most recent call last):
  File "C:\Users\15097\Desktop\FinalBlog\venv\Lib\site-packages\sqlalchemy\engine\base.py", line 1967, in _exec_single_context
    self.dialect.do_execute(
  File "C:\Users\15097\Desktop\FinalBlog\venv\Lib\site-packages\sqlalchemy\engine\default.py", line 924, in do_execute
    cursor.execute(statement, parameters)
sqlite3.OperationalError: no such column: post.author

The above exception was the direct cause of the following exception:

Traceback (most recent call last):
  File "C:\Users\15097\Desktop\FinalBlog\venv\Lib\site-packages\flask\app.py", line 1473, in wsgi_app
    response = self.full_dispatch_request()
               ^^^^^^^^^^^^^^^^^^^^^^^^^^^^
  File "C:\Users\15097\Desktop\FinalBlog\venv\Lib\site-packages\flask\app.py", line 882, in full_dispatch_request
    rv = self.handle_user_exception(e)
         ^^^^^^^^^^^^^^^^^^^^^^^^^^^^^
  File "C:\Users\15097\Desktop\FinalBlog\venv\Lib\site-packages\flask\app.py", line 880, in full_dispatch_request
    rv = self.dispatch_request()
         ^^^^^^^^^^^^^^^^^^^^^^^
  File "C:\Users\15097\Desktop\FinalBlog\venv\Lib\site-packages\flask\app.py", line 865, in dispatch_request
    return self.ensure_sync(self.view_functions[rule.endpoint])(**view_args)  # type: ignore[no-any-return]
           ^^^^^^^^^^^^^^^^^^^^^^^^^^^^^^^^^^^^^^^^^^^^^^^^^^^^^^^^^^^^^^^^^
  File "C:\Users\15097\Desktop\FinalBlog\venv\Lib\site-packages\flask_caching\__init__.py", line 426, in decorated_function
    rv = self._call_fn(f, *args, **kwargs)
         ^^^^^^^^^^^^^^^^^^^^^^^^^^^^^^^^^
  File "C:\Users\15097\Desktop\FinalBlog\venv\Lib\site-packages\flask_caching\__init__.py", line 185, in _call_fn
    return ensure_sync(fn)(*args, **kwargs)
           ^^^^^^^^^^^^^^^^^^^^^^^^^^^^^^^^
  File "C:\Users\15097\Desktop\FinalBlog\app.py", line 183, in home
    posts = Post.query.order_by(Post.date_posted.desc()).paginate(
            ^^^^^^^^^^^^^^^^^^^^^^^^^^^^^^^^^^^^^^^^^^^^^^^^^^^^^^
  File "C:\Users\15097\Desktop\FinalBlog\venv\Lib\site-packages\flask_sqlalchemy\query.py", line 98, in paginate
    return QueryPagination(
           ^^^^^^^^^^^^^^^^
  File "C:\Users\15097\Desktop\FinalBlog\venv\Lib\site-packages\flask_sqlalchemy\pagination.py", line 72, in __init__
    items = self._query_items()
            ^^^^^^^^^^^^^^^^^^^
  File "C:\Users\15097\Desktop\FinalBlog\venv\Lib\site-packages\flask_sqlalchemy\pagination.py", line 358, in _query_items
    out = query.limit(self.per_page).offset(self._query_offset).all()
          ^^^^^^^^^^^^^^^^^^^^^^^^^^^^^^^^^^^^^^^^^^^^^^^^^^^^^^^^^^^
  File "C:\Users\15097\Desktop\FinalBlog\venv\Lib\site-packages\sqlalchemy\orm\query.py", line 2673, in all
    return self._iter().all()  # type: ignore
           ^^^^^^^^^^^^
  File "C:\Users\15097\Desktop\FinalBlog\venv\Lib\site-packages\sqlalchemy\orm\query.py", line 2827, in _iter
    result: Union[ScalarResult[_T], Result[_T]] = self.session.execute(
                                                  ^^^^^^^^^^^^^^^^^^^^^
  File "C:\Users\15097\Desktop\FinalBlog\venv\Lib\site-packages\sqlalchemy\orm\session.py", line 2351, in execute
    return self._execute_internal(
           ^^^^^^^^^^^^^^^^^^^^^^^
  File "C:\Users\15097\Desktop\FinalBlog\venv\Lib\site-packages\sqlalchemy\orm\session.py", line 2236, in _execute_internal
    result: Result[Any] = compile_state_cls.orm_execute_statement(
                          ^^^^^^^^^^^^^^^^^^^^^^^^^^^^^^^^^^^^^^^^
  File "C:\Users\15097\Desktop\FinalBlog\venv\Lib\site-packages\sqlalchemy\orm\context.py", line 293, in orm_execute_statement
    result = conn.execute(
             ^^^^^^^^^^^^^
  File "C:\Users\15097\Desktop\FinalBlog\venv\Lib\site-packages\sqlalchemy\engine\base.py", line 1418, in execute
    return meth(
           ^^^^^
  File "C:\Users\15097\Desktop\FinalBlog\venv\Lib\site-packages\sqlalchemy\sql\elements.py", line 515, in _execute_on_connection
    return connection._execute_clauseelement(
           ^^^^^^^^^^^^^^^^^^^^^^^^^^^^^^^^^^
  File "C:\Users\15097\Desktop\FinalBlog\venv\Lib\site-packages\sqlalchemy\engine\base.py", line 1640, in _execute_clauseelement
    ret = self._execute_context(
          ^^^^^^^^^^^^^^^^^^^^^^
  File "C:\Users\15097\Desktop\FinalBlog\venv\Lib\site-packages\sqlalchemy\engine\base.py", line 1846, in _execute_context
    return self._exec_single_context(
           ^^^^^^^^^^^^^^^^^^^^^^^^^^
  File "C:\Users\15097\Desktop\FinalBlog\venv\Lib\site-packages\sqlalchemy\engine\base.py", line 1986, in _exec_single_context
    self._handle_dbapi_exception(
  File "C:\Users\15097\Desktop\FinalBlog\venv\Lib\site-packages\sqlalchemy\engine\base.py", line 2353, in _handle_dbapi_exception
    raise sqlalchemy_exception.with_traceback(exc_info[2]) from e
  File "C:\Users\15097\Desktop\FinalBlog\venv\Lib\site-packages\sqlalchemy\engine\base.py", line 1967, in _exec_single_context
    self.dialect.do_execute(
  File "C:\Users\15097\Desktop\FinalBlog\venv\Lib\site-packages\sqlalchemy\engine\default.py", line 924, in do_execute
    cursor.execute(statement, parameters)
sqlalchemy.exc.OperationalError: (sqlite3.OperationalError) no such column: post.author
[SQL: SELECT post.id AS post_id, post.title AS post_title, post.date_posted AS post_date_posted, post.content AS post_content, post.media_filename AS post_media_filename, post.author AS post_author, post.user_id AS post_user_id 
FROM post ORDER BY post.date_posted DESC
 LIMIT ? OFFSET ?]
[parameters: (10, 0)]
(Background on this error at: https://sqlalche.me/e/20/e3q8)
2024-07-11 18:31:38,818 INFO: Blog startup [in C:\Users\15097\Desktop\FinalBlog\app.py:112]
2024-07-11 18:31:40,587 ERROR: Exception on / [GET] [in C:\Users\15097\Desktop\FinalBlog\venv\Lib\site-packages\flask\app.py:838]
Traceback (most recent call last):
  File "C:\Users\15097\Desktop\FinalBlog\venv\Lib\site-packages\flask\app.py", line 1473, in wsgi_app
    response = self.full_dispatch_request()
               ^^^^^^^^^^^^^^^^^^^^^^^^^^^^
  File "C:\Users\15097\Desktop\FinalBlog\venv\Lib\site-packages\flask\app.py", line 882, in full_dispatch_request
    rv = self.handle_user_exception(e)
         ^^^^^^^^^^^^^^^^^^^^^^^^^^^^^
  File "C:\Users\15097\Desktop\FinalBlog\venv\Lib\site-packages\flask\app.py", line 880, in full_dispatch_request
    rv = self.dispatch_request()
         ^^^^^^^^^^^^^^^^^^^^^^^
  File "C:\Users\15097\Desktop\FinalBlog\venv\Lib\site-packages\flask\app.py", line 865, in dispatch_request
    return self.ensure_sync(self.view_functions[rule.endpoint])(**view_args)  # type: ignore[no-any-return]
           ^^^^^^^^^^^^^^^^^^^^^^^^^^^^^^^^^^^^^^^^^^^^^^^^^^^^^^^^^^^^^^^^^
  File "C:\Users\15097\Desktop\FinalBlog\venv\Lib\site-packages\flask_caching\__init__.py", line 426, in decorated_function
    rv = self._call_fn(f, *args, **kwargs)
         ^^^^^^^^^^^^^^^^^^^^^^^^^^^^^^^^^
  File "C:\Users\15097\Desktop\FinalBlog\venv\Lib\site-packages\flask_caching\__init__.py", line 185, in _call_fn
    return ensure_sync(fn)(*args, **kwargs)
           ^^^^^^^^^^^^^^^^^^^^^^^^^^^^^^^^
  File "C:\Users\15097\Desktop\FinalBlog\app.py", line 183, in home
    posts = Post.query.order_by(Post.date_posted.desc()).paginate(
            ^^^^^^^^^^
  File "C:\Users\15097\Desktop\FinalBlog\venv\Lib\site-packages\flask_sqlalchemy\model.py", line 22, in __get__
    return cls.query_class(
           ^^^^^^^^^^^^^^^^
  File "C:\Users\15097\Desktop\FinalBlog\venv\Lib\site-packages\sqlalchemy\orm\query.py", line 275, in __init__
    self._set_entities(entities)
  File "C:\Users\15097\Desktop\FinalBlog\venv\Lib\site-packages\sqlalchemy\orm\query.py", line 288, in _set_entities
    coercions.expect(
  File "C:\Users\15097\Desktop\FinalBlog\venv\Lib\site-packages\sqlalchemy\sql\coercions.py", line 389, in expect
    insp._post_inspect
  File "C:\Users\15097\Desktop\FinalBlog\venv\Lib\site-packages\sqlalchemy\util\langhelpers.py", line 1253, in __get__
    obj.__dict__[self.__name__] = result = self.fget(obj)
                                           ^^^^^^^^^^^^^^
  File "C:\Users\15097\Desktop\FinalBlog\venv\Lib\site-packages\sqlalchemy\orm\mapper.py", line 2711, in _post_inspect
    self._check_configure()
  File "C:\Users\15097\Desktop\FinalBlog\venv\Lib\site-packages\sqlalchemy\orm\mapper.py", line 2388, in _check_configure
    _configure_registries({self.registry}, cascade=True)
  File "C:\Users\15097\Desktop\FinalBlog\venv\Lib\site-packages\sqlalchemy\orm\mapper.py", line 4204, in _configure_registries
    _do_configure_registries(registries, cascade)
  File "C:\Users\15097\Desktop\FinalBlog\venv\Lib\site-packages\sqlalchemy\orm\mapper.py", line 4245, in _do_configure_registries
    mapper._post_configure_properties()
  File "C:\Users\15097\Desktop\FinalBlog\venv\Lib\site-packages\sqlalchemy\orm\mapper.py", line 2405, in _post_configure_properties
    prop.init()
  File "C:\Users\15097\Desktop\FinalBlog\venv\Lib\site-packages\sqlalchemy\orm\interfaces.py", line 584, in init
    self.do_init()
  File "C:\Users\15097\Desktop\FinalBlog\venv\Lib\site-packages\sqlalchemy\orm\relationships.py", line 1647, in do_init
    self._generate_backref()
  File "C:\Users\15097\Desktop\FinalBlog\venv\Lib\site-packages\sqlalchemy\orm\relationships.py", line 2075, in _generate_backref
    raise sa_exc.ArgumentError(
sqlalchemy.exc.ArgumentError: Error creating backref 'posts' on relationship 'Post.author': property of that name exists on mapper 'Mapper[User(user)]'
2024-07-11 18:32:33,152 INFO: Blog startup [in C:\Users\15097\Desktop\FinalBlog\app.py:112]
2024-07-11 18:33:45,836 INFO: Blog startup [in C:\Users\15097\Desktop\FinalBlog\app.py:112]
2024-07-11 18:34:26,435 INFO: Blog startup [in C:\Users\15097\Desktop\FinalBlog\app.py:112]
2024-07-11 18:34:50,463 INFO: Blog startup [in C:\Users\15097\Desktop\FinalBlog\app.py:112]
2024-07-11 18:35:23,734 INFO: Blog startup [in C:\Users\15097\Desktop\FinalBlog\app.py:112]
