2024-07-11 19:16:36,591 ERROR: Exception on /profile/Chris [GET] [in C:\Users\15097\Desktop\FinalBlog\venv\Lib\site-packages\flask\app.py:838]
Traceback (most recent call last):
  File "C:\Users\15097\Desktop\FinalBlog\venv\Lib\site-packages\flask\app.py", line 1473, in wsgi_app
    response = self.full_dispatch_request()
               ^^^^^^^^^^^^^^^^^^^^^^^^^^^^
  File "C:\Users\15097\Desktop\FinalBlog\venv\Lib\site-packages\flask\app.py", line 882, in full_dispatch_request
    rv = self.handle_user_exception(e)
         ^^^^^^^^^^^^^^^^^^^^^^^^^^^^^
  File "C:\Users\15097\Desktop\FinalBlog\venv\Lib\site-packages\flask\app.py", line 880, in full_dispatch_request
    rv = self.dispatch_request()
         ^^^^^^^^^^^^^^^^^^^^^^^
  File "C:\Users\15097\Desktop\FinalBlog\venv\Lib\site-packages\flask\app.py", line 865, in dispatch_request
    return self.ensure_sync(self.view_functions[rule.endpoint])(**view_args)  # type: ignore[no-any-return]
           ^^^^^^^^^^^^^^^^^^^^^^^^^^^^^^^^^^^^^^^^^^^^^^^^^^^^^^^^^^^^^^^^^
  File "C:\Users\15097\Desktop\FinalBlog\venv\Lib\site-packages\flask_login\utils.py", line 290, in decorated_view
    return current_app.ensure_sync(func)(*args, **kwargs)
           ^^^^^^^^^^^^^^^^^^^^^^^^^^^^^^^^^^^^^^^^^^^^^^
  File "C:\Users\15097\Desktop\FinalBlog\app.py", line 434, in profile
    form.social_media.data = current_user.social_media
                             ^^^^^^^^^^^^^^^^^^^^^^^^^
AttributeError: 'User' object has no attribute 'social_media'
2024-07-11 19:23:02,792 INFO: Blog startup [in C:\Users\15097\Desktop\FinalBlog\app.py:112]
2024-07-11 19:23:05,549 ERROR: Exception on /profile/Chris [GET] [in C:\Users\15097\Desktop\FinalBlog\venv\Lib\site-packages\flask\app.py:838]
Traceback (most recent call last):
  File "C:\Users\15097\Desktop\FinalBlog\venv\Lib\site-packages\flask\app.py", line 1473, in wsgi_app
    response = self.full_dispatch_request()
               ^^^^^^^^^^^^^^^^^^^^^^^^^^^^
  File "C:\Users\15097\Desktop\FinalBlog\venv\Lib\site-packages\flask\app.py", line 882, in full_dispatch_request
    rv = self.handle_user_exception(e)
         ^^^^^^^^^^^^^^^^^^^^^^^^^^^^^
  File "C:\Users\15097\Desktop\FinalBlog\venv\Lib\site-packages\flask\app.py", line 880, in full_dispatch_request
    rv = self.dispatch_request()
         ^^^^^^^^^^^^^^^^^^^^^^^
  File "C:\Users\15097\Desktop\FinalBlog\venv\Lib\site-packages\flask\app.py", line 865, in dispatch_request
    return self.ensure_sync(self.view_functions[rule.endpoint])(**view_args)  # type: ignore[no-any-return]
           ^^^^^^^^^^^^^^^^^^^^^^^^^^^^^^^^^^^^^^^^^^^^^^^^^^^^^^^^^^^^^^^^^
  File "C:\Users\15097\Desktop\FinalBlog\venv\Lib\site-packages\flask_login\utils.py", line 290, in decorated_view
    return current_app.ensure_sync(func)(*args, **kwargs)
           ^^^^^^^^^^^^^^^^^^^^^^^^^^^^^^^^^^^^^^^^^^^^^^
  File "C:\Users\15097\Desktop\FinalBlog\app.py", line 433, in profile
    form.social_media.data = current_user.social_media
                             ^^^^^^^^^^^^^^^^^^^^^^^^^
AttributeError: 'User' object has no attribute 'social_media'
2024-07-11 19:23:08,794 ERROR: Exception on /profile/Chris [GET] [in C:\Users\15097\Desktop\FinalBlog\venv\Lib\site-packages\flask\app.py:838]
Traceback (most recent call last):
  File "C:\Users\15097\Desktop\FinalBlog\venv\Lib\site-packages\flask\app.py", line 1473, in wsgi_app
    response = self.full_dispatch_request()
               ^^^^^^^^^^^^^^^^^^^^^^^^^^^^
  File "C:\Users\15097\Desktop\FinalBlog\venv\Lib\site-packages\flask\app.py", line 882, in full_dispatch_request
    rv = self.handle_user_exception(e)
         ^^^^^^^^^^^^^^^^^^^^^^^^^^^^^
  File "C:\Users\15097\Desktop\FinalBlog\venv\Lib\site-packages\flask\app.py", line 880, in full_dispatch_request
    rv = self.dispatch_request()
         ^^^^^^^^^^^^^^^^^^^^^^^
  File "C:\Users\15097\Desktop\FinalBlog\venv\Lib\site-packages\flask\app.py", line 865, in dispatch_request
    return self.ensure_sync(self.view_functions[rule.endpoint])(**view_args)  # type: ignore[no-any-return]
           ^^^^^^^^^^^^^^^^^^^^^^^^^^^^^^^^^^^^^^^^^^^^^^^^^^^^^^^^^^^^^^^^^
  File "C:\Users\15097\Desktop\FinalBlog\venv\Lib\site-packages\flask_login\utils.py", line 290, in decorated_view
    return current_app.ensure_sync(func)(*args, **kwargs)
           ^^^^^^^^^^^^^^^^^^^^^^^^^^^^^^^^^^^^^^^^^^^^^^
  File "C:\Users\15097\Desktop\FinalBlog\app.py", line 433, in profile
    form.social_media.data = current_user.social_media
                             ^^^^^^^^^^^^^^^^^^^^^^^^^
AttributeError: 'User' object has no attribute 'social_media'
2024-07-11 19:23:41,242 INFO: Blog startup [in C:\Users\15097\Desktop\FinalBlog\app.py:112]
2024-07-11 19:23:42,995 ERROR: Exception on /profile/Chris [GET] [in C:\Users\15097\Desktop\FinalBlog\venv\Lib\site-packages\flask\app.py:838]
Traceback (most recent call last):
  File "C:\Users\15097\Desktop\FinalBlog\venv\Lib\site-packages\flask\app.py", line 1473, in wsgi_app
    response = self.full_dispatch_request()
               ^^^^^^^^^^^^^^^^^^^^^^^^^^^^
  File "C:\Users\15097\Desktop\FinalBlog\venv\Lib\site-packages\flask\app.py", line 882, in full_dispatch_request
    rv = self.handle_user_exception(e)
         ^^^^^^^^^^^^^^^^^^^^^^^^^^^^^
  File "C:\Users\15097\Desktop\FinalBlog\venv\Lib\site-packages\flask\app.py", line 880, in full_dispatch_request
    rv = self.dispatch_request()
         ^^^^^^^^^^^^^^^^^^^^^^^
  File "C:\Users\15097\Desktop\FinalBlog\venv\Lib\site-packages\flask\app.py", line 865, in dispatch_request
    return self.ensure_sync(self.view_functions[rule.endpoint])(**view_args)  # type: ignore[no-any-return]
           ^^^^^^^^^^^^^^^^^^^^^^^^^^^^^^^^^^^^^^^^^^^^^^^^^^^^^^^^^^^^^^^^^
  File "C:\Users\15097\Desktop\FinalBlog\venv\Lib\site-packages\flask_login\utils.py", line 290, in decorated_view
    return current_app.ensure_sync(func)(*args, **kwargs)
           ^^^^^^^^^^^^^^^^^^^^^^^^^^^^^^^^^^^^^^^^^^^^^^
  File "C:\Users\15097\Desktop\FinalBlog\app.py", line 436, in profile
    Post.query.filter_by(author=user.username)
  File "C:\Users\15097\Desktop\FinalBlog\venv\Lib\site-packages\sqlalchemy\orm\query.py", line 1984, in filter_by
    _entity_namespace_key(from_entity, key) == value
  File "C:\Users\15097\Desktop\FinalBlog\venv\Lib\site-packages\sqlalchemy\sql\operators.py", line 582, in __eq__
    return self.operate(eq, other)
           ^^^^^^^^^^^^^^^^^^^^^^^
  File "C:\Users\15097\Desktop\FinalBlog\venv\Lib\site-packages\sqlalchemy\orm\attributes.py", line 453, in operate
    return op(self.comparator, *other, **kwargs)  # type: ignore[no-any-return]  # noqa: E501
           ^^^^^^^^^^^^^^^^^^^^^^^^^^^^^^^^^^^^^
  File "C:\Users\15097\Desktop\FinalBlog\venv\Lib\site-packages\sqlalchemy\orm\relationships.py", line 762, in __eq__
    self.property._optimized_compare(
  File "C:\Users\15097\Desktop\FinalBlog\venv\Lib\site-packages\sqlalchemy\orm\relationships.py", line 1185, in _optimized_compare
    raise sa_exc.ArgumentError(
sqlalchemy.exc.ArgumentError: Mapped instance expected for relationship comparison to object.   Classes, queries and other SQL elements are not accepted in this context; for comparison with a subquery, use Post.author.has(**criteria).
2024-07-11 19:23:47,975 ERROR: Exception on /profile/Chris [GET] [in C:\Users\15097\Desktop\FinalBlog\venv\Lib\site-packages\flask\app.py:838]
Traceback (most recent call last):
  File "C:\Users\15097\Desktop\FinalBlog\venv\Lib\site-packages\flask\app.py", line 1473, in wsgi_app
    response = self.full_dispatch_request()
               ^^^^^^^^^^^^^^^^^^^^^^^^^^^^
  File "C:\Users\15097\Desktop\FinalBlog\venv\Lib\site-packages\flask\app.py", line 882, in full_dispatch_request
    rv = self.handle_user_exception(e)
         ^^^^^^^^^^^^^^^^^^^^^^^^^^^^^
  File "C:\Users\15097\Desktop\FinalBlog\venv\Lib\site-packages\flask\app.py", line 880, in full_dispatch_request
    rv = self.dispatch_request()
         ^^^^^^^^^^^^^^^^^^^^^^^
  File "C:\Users\15097\Desktop\FinalBlog\venv\Lib\site-packages\flask\app.py", line 865, in dispatch_request
    return self.ensure_sync(self.view_functions[rule.endpoint])(**view_args)  # type: ignore[no-any-return]
           ^^^^^^^^^^^^^^^^^^^^^^^^^^^^^^^^^^^^^^^^^^^^^^^^^^^^^^^^^^^^^^^^^
  File "C:\Users\15097\Desktop\FinalBlog\venv\Lib\site-packages\flask_login\utils.py", line 290, in decorated_view
    return current_app.ensure_sync(func)(*args, **kwargs)
           ^^^^^^^^^^^^^^^^^^^^^^^^^^^^^^^^^^^^^^^^^^^^^^
  File "C:\Users\15097\Desktop\FinalBlog\app.py", line 436, in profile
    Post.query.filter_by(author=user.username)
  File "C:\Users\15097\Desktop\FinalBlog\venv\Lib\site-packages\sqlalchemy\orm\query.py", line 1984, in filter_by
    _entity_namespace_key(from_entity, key) == value
  File "C:\Users\15097\Desktop\FinalBlog\venv\Lib\site-packages\sqlalchemy\sql\operators.py", line 582, in __eq__
    return self.operate(eq, other)
           ^^^^^^^^^^^^^^^^^^^^^^^
  File "C:\Users\15097\Desktop\FinalBlog\venv\Lib\site-packages\sqlalchemy\orm\attributes.py", line 453, in operate
    return op(self.comparator, *other, **kwargs)  # type: ignore[no-any-return]  # noqa: E501
           ^^^^^^^^^^^^^^^^^^^^^^^^^^^^^^^^^^^^^
  File "C:\Users\15097\Desktop\FinalBlog\venv\Lib\site-packages\sqlalchemy\orm\relationships.py", line 762, in __eq__
    self.property._optimized_compare(
  File "C:\Users\15097\Desktop\FinalBlog\venv\Lib\site-packages\sqlalchemy\orm\relationships.py", line 1185, in _optimized_compare
    raise sa_exc.ArgumentError(
sqlalchemy.exc.ArgumentError: Mapped instance expected for relationship comparison to object.   Classes, queries and other SQL elements are not accepted in this context; for comparison with a subquery, use Post.author.has(**criteria).
2024-07-11 19:24:20,759 INFO: Blog startup [in C:\Users\15097\Desktop\FinalBlog\app.py:112]
